<?xml version="1.0"?>
<robot name="dora">

    <!-- Base Link -->
    <link name="base_link">
        <inertial>
            <mass value="5.0" />
            <origin xyz="0 0 0" />
            <inertia ixx="0.1" iyy="0.1" izz="0.1" ixy="0.0" ixz="0.0" iyz="0.0" />
        </inertial>
        <visual>
            <geometry>
                <mesh filename="DORA_robot.stl" />
            </geometry>
        </visual>
        <collision>
            <geometry>
                <mesh filename="DORA_robot.stl" />
            </geometry>
        </collision>
    </link>

    <!-- Omni Wheels -->
    <joint name="wheel_1_joint" type="continuous">
        <parent link="base_link" />
        <child link="wheel_1" />
        <origin xyz="0.5 -0.288 0" rpy="0 0 0" />
        <axis xyz="0 0 1" />
    </joint>

    <link name="wheel_1">
        <visual>
            <geometry>
                <cylinder radius="0.05" length="0.02" />
            </geometry>
        </visual>
    </link>

    <joint name="wheel_2_joint" type="continuous">
        <parent link="base_link" />
        <child link="wheel_2" />
        <origin xyz="-0.5 -0.288 0" rpy="0 0 0" />
        <axis xyz="0 0 1" />
    </joint>

    <link name="wheel_2">
        <visual>
            <geometry>
                <cylinder radius="0.05" length="0.02" />
            </geometry>
        </visual>
    </link>

    <joint name="wheel_3_joint" type="continuous">
        <parent link="base_link" />
        <child link="wheel_3" />
        <origin xyz="0 0.577 0" rpy="0 0 0" />
        <axis xyz="0 0 1" />
    </joint>

    <link name="wheel_3">
        <visual>
            <geometry>
                <cylinder radius="0.05" length="0.02" />
            </geometry>
        </visual>
    </link>

</robot>
