<?xml version="1.0"?>
<robot name="dora" xmlns:xacro="http://www.ros.org/wiki/xacro">

    <xacro:property name="body_height" value="0.5" />
    <xacro:property name="body_scale" value="0.005" />

    <xacro:property name="body_pos" value="0 0 ${body_height * body_scale}" />
    <xacro:property name="body_scale_xyz" value="${body_scale} ${body_scale} ${body_scale}" />

    <!-- Base Link -->
    <link name="base_link">
        <visual>
            <origin xyz="${body_pos}" />

            <geometry>
                <!-- <mesh filename="dora_vaz.stl" /> -->
                <mesh filename="package://dora_urdf_rviz2/meshes/dora_vaz.stl"
                    scale="${body_scale_xyz}" />
            </geometry>

            <material name="wood">
                <color rgba="0.96 0.73 0.53 1" />
            </material>
        </visual>

        <collision>
            <origin xyz="${body_pos}" />

            <geometry>
                <!-- <mesh filename="dora_vaz.stl" /> -->
                <mesh filename="package://dora_urdf_rviz2/meshes/dora_vaz.stl"
                    scale="${body_scale_xyz}" />
            </geometry>
        </collision>
    </link>

    <xacro:macro name="omniwheel" params="idx">
        <xacro:property name="angle" value='${0.5 * pi + 2 * pi * idx / 3}' />

        <joint name="wheel_joint_${idx}" type="continuous">
            <parent link="base_link" />
            <child link="wheel_${idx}" />
            <origin xyz="${cos(angle)} ${sin(angle)} ${-body_height * 0.25}" rpy="0 0 0" />
            <axis xyz="${cos(angle)} ${sin(angle)} 0" />
        </joint>

        <link name="wheel_${idx}">
            <collision>
                <origin rpy="${0.5 * pi} ${0.5 * pi} ${angle - 0.5 * pi}" />

                <geometry>
                    <cylinder radius="0.1" length="0.02" />
                </geometry>
            </collision>

            <visual>
                <origin rpy="${0.5 * pi} ${0.5 * pi} ${angle - 0.5 * pi}" />

                <geometry>
                    <cylinder radius="0.1" length="0.02" />
                </geometry>
            </visual>
        </link>
    </xacro:macro>

    <xacro:omniwheel idx="0" />
    <xacro:omniwheel idx="1" />
    <xacro:omniwheel idx="2" />
</robot>
